[2022-06-01 19:29:15,428] {taskinstance.py:1032} INFO - Dependencies all met for <TaskInstance: PostgresIngestionDAG.ingest scheduled__2022-01-28T16:00:00+00:00 [queued]>
[2022-06-01 19:29:15,468] {taskinstance.py:1032} INFO - Dependencies all met for <TaskInstance: PostgresIngestionDAG.ingest scheduled__2022-01-28T16:00:00+00:00 [queued]>
[2022-06-01 19:29:15,468] {taskinstance.py:1238} INFO - 
--------------------------------------------------------------------------------
[2022-06-01 19:29:15,468] {taskinstance.py:1239} INFO - Starting attempt 2 of 2
[2022-06-01 19:29:15,469] {taskinstance.py:1240} INFO - 
--------------------------------------------------------------------------------
[2022-06-01 19:29:15,506] {taskinstance.py:1259} INFO - Executing <Task(PythonOperator): ingest> on 2022-01-28 16:00:00+00:00
[2022-06-01 19:29:15,524] {standard_task_runner.py:52} INFO - Started process 1220 to run task
[2022-06-01 19:29:15,568] {standard_task_runner.py:76} INFO - Running: ['***', 'tasks', 'run', 'PostgresIngestionDAG', 'ingest', 'scheduled__2022-01-28T16:00:00+00:00', '--job-id', '121', '--raw', '--subdir', 'DAGS_FOLDER/ingest_to_postgres.py', '--cfg-path', '/tmp/tmpmt541ttv', '--error-file', '/tmp/tmp0vkhgg1z']
[2022-06-01 19:29:15,593] {standard_task_runner.py:77} INFO - Job 121: Subtask ingest
[2022-06-01 19:29:15,821] {logging_mixin.py:109} INFO - Running <TaskInstance: PostgresIngestionDAG.ingest scheduled__2022-01-28T16:00:00+00:00 [running]> on host 45f40c91492d
[2022-06-01 19:29:15,987] {warnings.py:110} WARNING - /home/***/.local/lib/python3.7/site-packages/***/utils/context.py:152: AirflowContextDeprecationWarning: Accessing 'execution_date' from the template is deprecated and will be removed in a future version. Please use 'data_interval_start' or 'logical_date' instead.
  warnings.warn(_create_deprecation_warning(key, self._deprecation_replacements[key]))

[2022-06-01 19:29:16,123] {taskinstance.py:1426} INFO - Exporting the following env vars:
AIRFLOW_CTX_DAG_OWNER=***
AIRFLOW_CTX_DAG_ID=PostgresIngestionDAG
AIRFLOW_CTX_TASK_ID=ingest
AIRFLOW_CTX_EXECUTION_DATE=2022-01-28T16:00:00+00:00
AIRFLOW_CTX_DAG_RUN_ID=scheduled__2022-01-28T16:00:00+00:00
[2022-06-01 19:29:16,124] {logging_mixin.py:109} INFO - fhv_trip_record_2022-01 file_2022-01.csv
[2022-06-01 19:29:35,659] {taskinstance.py:1700} ERROR - Task failed with exception
Traceback (most recent call last):
  File "/home/airflow/.local/lib/python3.7/site-packages/airflow/models/taskinstance.py", line 1329, in _run_raw_task
    self._execute_task_with_callbacks(context)
  File "/home/airflow/.local/lib/python3.7/site-packages/airflow/models/taskinstance.py", line 1455, in _execute_task_with_callbacks
    result = self._execute_task(context, self.task)
  File "/home/airflow/.local/lib/python3.7/site-packages/airflow/models/taskinstance.py", line 1511, in _execute_task
    result = execute_callable(context=context)
  File "/home/airflow/.local/lib/python3.7/site-packages/airflow/operators/python.py", line 174, in execute
    return_value = self.execute_callable()
  File "/home/airflow/.local/lib/python3.7/site-packages/airflow/operators/python.py", line 185, in execute_callable
    return self.python_callable(*self.op_args, **self.op_kwargs)
  File "/opt/airflow/dags/ingest_script.py", line 19, in ingest_callable
    df.tpep_pickup_datetime = pd.to_datetime(df.tpep_pickup_datetime)
  File "/home/airflow/.local/lib/python3.7/site-packages/pandas/core/generic.py", line 5487, in __getattr__
    return object.__getattribute__(self, name)
AttributeError: 'DataFrame' object has no attribute 'tpep_pickup_datetime'
[2022-06-01 19:29:35,715] {taskinstance.py:1277} INFO - Marking task as FAILED. dag_id=PostgresIngestionDAG, task_id=ingest, execution_date=20220128T160000, start_date=20220601T192915, end_date=20220601T192935
[2022-06-01 19:29:36,083] {standard_task_runner.py:92} ERROR - Failed to execute job 121 for task ingest
Traceback (most recent call last):
  File "/home/airflow/.local/lib/python3.7/site-packages/airflow/task/task_runner/standard_task_runner.py", line 85, in _start_by_fork
    args.func(args, dag=self.dag)
  File "/home/airflow/.local/lib/python3.7/site-packages/airflow/cli/cli_parser.py", line 48, in command
    return func(*args, **kwargs)
  File "/home/airflow/.local/lib/python3.7/site-packages/airflow/utils/cli.py", line 92, in wrapper
    return f(*args, **kwargs)
  File "/home/airflow/.local/lib/python3.7/site-packages/airflow/cli/commands/task_command.py", line 298, in task_run
    _run_task_by_selected_method(args, dag, ti)
  File "/home/airflow/.local/lib/python3.7/site-packages/airflow/cli/commands/task_command.py", line 107, in _run_task_by_selected_method
    _run_raw_task(args, ti)
  File "/home/airflow/.local/lib/python3.7/site-packages/airflow/cli/commands/task_command.py", line 184, in _run_raw_task
    error_file=args.error_file,
  File "/home/airflow/.local/lib/python3.7/site-packages/airflow/utils/session.py", line 70, in wrapper
    return func(*args, session=session, **kwargs)
  File "/home/airflow/.local/lib/python3.7/site-packages/airflow/models/taskinstance.py", line 1329, in _run_raw_task
    self._execute_task_with_callbacks(context)
  File "/home/airflow/.local/lib/python3.7/site-packages/airflow/models/taskinstance.py", line 1455, in _execute_task_with_callbacks
    result = self._execute_task(context, self.task)
  File "/home/airflow/.local/lib/python3.7/site-packages/airflow/models/taskinstance.py", line 1511, in _execute_task
    result = execute_callable(context=context)
  File "/home/airflow/.local/lib/python3.7/site-packages/airflow/operators/python.py", line 174, in execute
    return_value = self.execute_callable()
  File "/home/airflow/.local/lib/python3.7/site-packages/airflow/operators/python.py", line 185, in execute_callable
    return self.python_callable(*self.op_args, **self.op_kwargs)
  File "/opt/airflow/dags/ingest_script.py", line 19, in ingest_callable
    df.tpep_pickup_datetime = pd.to_datetime(df.tpep_pickup_datetime)
  File "/home/airflow/.local/lib/python3.7/site-packages/pandas/core/generic.py", line 5487, in __getattr__
    return object.__getattribute__(self, name)
AttributeError: 'DataFrame' object has no attribute 'tpep_pickup_datetime'
[2022-06-01 19:29:36,204] {local_task_job.py:212} WARNING - State of this instance has been externally set to failed. Terminating instance.
[2022-06-01 19:29:36,212] {process_utils.py:124} INFO - Sending Signals.SIGTERM to group 1220. PIDs of all processes in the group: [1220]
[2022-06-01 19:29:36,222] {process_utils.py:75} INFO - Sending the signal Signals.SIGTERM to group 1220
[2022-06-01 19:29:36,228] {process_utils.py:70} INFO - Process psutil.Process(pid=1220, status='terminated', exitcode=1, started='19:29:14') (1220) terminated with exit code 1
