[2022-06-01 11:12:39,652] {taskinstance.py:1032} INFO - Dependencies all met for <TaskInstance: PostgresIngestionDAG.ingest manual__2022-06-01T10:41:09.901077+00:00 [queued]>
[2022-06-01 11:12:39,683] {taskinstance.py:1032} INFO - Dependencies all met for <TaskInstance: PostgresIngestionDAG.ingest manual__2022-06-01T10:41:09.901077+00:00 [queued]>
[2022-06-01 11:12:39,684] {taskinstance.py:1238} INFO - 
--------------------------------------------------------------------------------
[2022-06-01 11:12:39,684] {taskinstance.py:1239} INFO - Starting attempt 5 of 5
[2022-06-01 11:12:39,684] {taskinstance.py:1240} INFO - 
--------------------------------------------------------------------------------
[2022-06-01 11:12:39,714] {taskinstance.py:1259} INFO - Executing <Task(BashOperator): ingest> on 2022-06-01 10:41:09.901077+00:00
[2022-06-01 11:12:39,719] {standard_task_runner.py:52} INFO - Started process 2608 to run task
[2022-06-01 11:12:39,729] {standard_task_runner.py:76} INFO - Running: ['***', 'tasks', 'run', 'PostgresIngestionDAG', 'ingest', 'manual__2022-06-01T10:41:09.901077+00:00', '--job-id', '83', '--raw', '--subdir', 'DAGS_FOLDER/ingest_to_postgres.py', '--cfg-path', '/tmp/tmp7m3tirqp', '--error-file', '/tmp/tmp_7j_g6cx']
[2022-06-01 11:12:39,729] {standard_task_runner.py:77} INFO - Job 83: Subtask ingest
[2022-06-01 11:12:39,803] {logging_mixin.py:109} INFO - Running <TaskInstance: PostgresIngestionDAG.ingest manual__2022-06-01T10:41:09.901077+00:00 [running]> on host 5b72bd51239c
[2022-06-01 11:12:39,881] {taskinstance.py:1426} INFO - Exporting the following env vars:
AIRFLOW_CTX_DAG_OWNER=***
AIRFLOW_CTX_DAG_ID=PostgresIngestionDAG
AIRFLOW_CTX_TASK_ID=ingest
AIRFLOW_CTX_EXECUTION_DATE=2022-06-01T10:41:09.901077+00:00
AIRFLOW_CTX_DAG_RUN_ID=manual__2022-06-01T10:41:09.901077+00:00
[2022-06-01 11:12:39,885] {subprocess.py:62} INFO - Tmp dir root location: 
 /tmp
[2022-06-01 11:12:39,885] {subprocess.py:74} INFO - Running command: ['bash', '-c', 'ls /opt/*** && rm file.parquet && ls /opt/***']
[2022-06-01 11:12:39,897] {subprocess.py:85} INFO - Output:
[2022-06-01 11:12:39,903] {subprocess.py:89} INFO - ***-worker.pid
[2022-06-01 11:12:39,903] {subprocess.py:89} INFO - ***.cfg
[2022-06-01 11:12:39,904] {subprocess.py:89} INFO - dags
[2022-06-01 11:12:39,904] {subprocess.py:89} INFO - file.parquet
[2022-06-01 11:12:39,904] {subprocess.py:89} INFO - file_2022-06.parquet
[2022-06-01 11:12:39,904] {subprocess.py:89} INFO - google_credentials.json
[2022-06-01 11:12:39,904] {subprocess.py:89} INFO - logs
[2022-06-01 11:12:39,904] {subprocess.py:89} INFO - plugins
[2022-06-01 11:12:39,904] {subprocess.py:89} INFO - requirements.txt
[2022-06-01 11:12:39,904] {subprocess.py:89} INFO - webserver_config.py
[2022-06-01 11:12:39,910] {subprocess.py:89} INFO - rm: cannot remove 'file.parquet': No such file or directory
[2022-06-01 11:12:39,911] {subprocess.py:93} INFO - Command exited with return code 1
[2022-06-01 11:12:39,930] {taskinstance.py:1700} ERROR - Task failed with exception
Traceback (most recent call last):
  File "/home/airflow/.local/lib/python3.7/site-packages/airflow/models/taskinstance.py", line 1329, in _run_raw_task
    self._execute_task_with_callbacks(context)
  File "/home/airflow/.local/lib/python3.7/site-packages/airflow/models/taskinstance.py", line 1455, in _execute_task_with_callbacks
    result = self._execute_task(context, self.task)
  File "/home/airflow/.local/lib/python3.7/site-packages/airflow/models/taskinstance.py", line 1511, in _execute_task
    result = execute_callable(context=context)
  File "/home/airflow/.local/lib/python3.7/site-packages/airflow/operators/bash.py", line 188, in execute
    f'Bash command failed. The command returned a non-zero exit code {result.exit_code}.'
airflow.exceptions.AirflowException: Bash command failed. The command returned a non-zero exit code 1.
[2022-06-01 11:12:39,938] {taskinstance.py:1277} INFO - Marking task as FAILED. dag_id=PostgresIngestionDAG, task_id=ingest, execution_date=20220601T104109, start_date=20220601T111239, end_date=20220601T111239
[2022-06-01 11:12:39,960] {standard_task_runner.py:92} ERROR - Failed to execute job 83 for task ingest
Traceback (most recent call last):
  File "/home/airflow/.local/lib/python3.7/site-packages/airflow/task/task_runner/standard_task_runner.py", line 85, in _start_by_fork
    args.func(args, dag=self.dag)
  File "/home/airflow/.local/lib/python3.7/site-packages/airflow/cli/cli_parser.py", line 48, in command
    return func(*args, **kwargs)
  File "/home/airflow/.local/lib/python3.7/site-packages/airflow/utils/cli.py", line 92, in wrapper
    return f(*args, **kwargs)
  File "/home/airflow/.local/lib/python3.7/site-packages/airflow/cli/commands/task_command.py", line 298, in task_run
    _run_task_by_selected_method(args, dag, ti)
  File "/home/airflow/.local/lib/python3.7/site-packages/airflow/cli/commands/task_command.py", line 107, in _run_task_by_selected_method
    _run_raw_task(args, ti)
  File "/home/airflow/.local/lib/python3.7/site-packages/airflow/cli/commands/task_command.py", line 184, in _run_raw_task
    error_file=args.error_file,
  File "/home/airflow/.local/lib/python3.7/site-packages/airflow/utils/session.py", line 70, in wrapper
    return func(*args, session=session, **kwargs)
  File "/home/airflow/.local/lib/python3.7/site-packages/airflow/models/taskinstance.py", line 1329, in _run_raw_task
    self._execute_task_with_callbacks(context)
  File "/home/airflow/.local/lib/python3.7/site-packages/airflow/models/taskinstance.py", line 1455, in _execute_task_with_callbacks
    result = self._execute_task(context, self.task)
  File "/home/airflow/.local/lib/python3.7/site-packages/airflow/models/taskinstance.py", line 1511, in _execute_task
    result = execute_callable(context=context)
  File "/home/airflow/.local/lib/python3.7/site-packages/airflow/operators/bash.py", line 188, in execute
    f'Bash command failed. The command returned a non-zero exit code {result.exit_code}.'
airflow.exceptions.AirflowException: Bash command failed. The command returned a non-zero exit code 1.
[2022-06-01 11:12:39,982] {local_task_job.py:154} INFO - Task exited with return code 1
[2022-06-01 11:12:40,049] {local_task_job.py:264} INFO - 0 downstream tasks scheduled from follow-on schedule check
